Workbook

Sheet DATOS DE 2023 A 2026
A1: ULTIMA ACTUALIZACION | B1: 46082 | D1: FECHA DESDE ESTUDIO | E1: 44927
A2: SISTEMA ELECTRICO | B2: PENINSULAR | D2: Componentes precio energía cierre desglose | Red Eléctrica
A3: MAGNITUDES | B3: €/MWh
B5: ene/23 | C5: feb/23 | D5: mar/23 | E5: abr/23 | F5: may/23 | G5: jun/23 | H5: jul/23 | I5: ago/23 | J5: sep/23 | K5: oct/23 | L5: nov/23 | M5: dic/23 | N5: ene/24 | O5: feb/24 | P5: mar/24 | Q5: abr/24 | R5: may/24 | S5: jun/24 | T5: jul/24 | U5: ago/24 | V5: sep/24 | W5: oct/24 | X5: nov/24 | Y5: dic/24 | Z5: ene/25 | AA5: feb/25 | AB5: mar/25 | AC5: abr/25 | AD5: may/25 | AE5: jun/25 | AF5: jul/25 | AG5: ago/25 | AH5: sep/25 | AI5: oct/25 | AJ5: nov/25 | AK5: dic/25 | AL5: ene/26 | AM5: feb/26 | AN5: mar/26 | AO5: 46113 | AP5: 46143 | AQ5: 46174
A6: Mercado diario | B6: 73.17 | C6: 135.5 | D6: 92.01 | E6: 74.31 | F6: 74.34 | G6: 93.68 | H6: 90.93 | I6: 96.84 | J6: 104 | K6: 90.67 | L6: 65.98 | M6: 74.41 | N6: 76.87 | O6: 40.77 | P6: 21.36 | Q6: 14.1 | R6: 30.13 | S6: 56.84 | T6: 72.63 | U6: 91.3 | V6: 72.87 | W6: 70.12 | X6: 106.71 | Y6: 113.96 | Z6: 100.3 | AA6: 110.71 | AB6: 55.52 | AC6: 27.66 | AD6: 17.43 | AE6: 72.47 | AF6: 70.44 | AG6: 67.97 | AH6: 60.85 | AI6: 76.65 | AJ6: 60.52 | AK6: 80.19 | AL6: 73.48 | AM6: 18.09 | AN6: 44.6 | AO6: 42.95 | AP6: 54.87 | AQ6: 69.6
A7: Mercado intradiario (subastas MIBEL y continuo) | B7: -0.08 | C7: -0.08 | D7: -0.17 | E7: -0.27 | F7: -0.11 | G7: -0.05 | H7: -0.07 | I7: -0.05 | J7: -0.08 | K7: -0.12 | L7: -0.07 | M7: -0.08 | N7: -0.08 | O7: -0.09 | P7: -0.05 | Q7: -0.13 | R7: -0.06 | S7: -0.11 | T7: -0.07 | U7: -0.13 | V7: -0.09 | W7: -0.07 | X7: -0.09 | Y7: -0.08 | Z7: -0.1 | AA7: -0.1 | AB7: -0.1 | AC7: -0.01 | AD7: -0.07 | AE7: -0.13 | AF7: -0.15 | AG7: -0.1 | AH7: -0.14 | AI7: -0.21 | AJ7: -0.21 | AK7: -0.2 | AL7: -0.13 | AM7: -0.17 | AN7: -0.14 | AO7: -0.08 | AP7: -0.21 | AQ7: -0.12
A8: Restricciones técnicas PDBF | B8: 5.72 | C8: 2.61 | D8: 3.51 | E8: 5.12 | F8: 4.23 | G8: 2.66 | H8: 2.8 | I8: 2.72 | J8: 2.79 | K8: 5.09 | L8: 6 | M8: 4.03 | N8: 2.97 | O8: 4.03 | P8: 7.11 | Q8: 9.52 | R8: 8.97 | S8: 5.53 | T8: 3.39 | U8: 3.39 | V8: 4.45 | W8: 4.84 | X8: 4.96 | Y8: 4.1 | Z8: 4.2 | AA8: 4.06 | AB8: 6.63 | AC8: 11.26 | AD8: 21.56 | AE8: 9.68 | AF8: 8.42 | AG8: 8.31 | AH8: 10.04 | AI8: 11.08 | AJ8: 13.15 | AK8: 11.43 | AL8: 11.97 | AM8: 22.05 | AN8: 24.96 | AO8: 17.5 | AP8: 16.31 | AQ8: 12.74
A9: Banda de regulación secundaria | B9: 2.64 | C9: 1.69 | D9: 2.99 | E9: 3.06 | F9: 2.93 | G9: 2.04 | H9: 2.14 | I9: 1.97 | J9: 1.73 | K9: 2.75 | L9: 2.13 | M9: 1.91 | N9: 1.93 | O9: 1.81 | P9: 1.72 | Q9: 1.57 | R9: 1.92 | S9: 3.09 | T9: 1.69 | U9: 1.66 | V9: 2.1 | W9: 3.07 | X9: 3.22 | Y9: 3.69 | Z9: 3.3 | AA9: 3.56 | AB9: 2.54 | AC9: 1.7 | AD9: 1.27 | AE9: 1.29 | AF9: 1.83 | AG9: 2.14 | AH9: 2.36 | AI9: 2.29 | AJ9: 1.78 | AK9: 1.26 | AL9: 2.91 | AM9: 3.06 | AN9: 3.16 | AO9: 3.38 | AP9: 3.72 | AQ9: 3.36
A10: Restricciones técnicas en tiempo real | B10: 4.64 | C10: 3.46 | D10: 3.65 | E10: 2.36 | F10: 2.55 | G10: 3.34 | H10: 2.43 | I10: 2.72 | J10: 3.38 | K10: 5.38 | L10: 5.36 | M10: 4.44 | N10: 3.08 | O10: 3.15 | P10: 3.41 | Q10: 5.35 | R10: 3.07 | S10: 2.6 | T10: 2.79 | U10: 3.17 | V10: 3.61 | W10: 5.5 | X10: 4.03 | Y10: 3.59 | Z10: 3.56 | AA10: 7.08 | AB10: 5.85 | AC10: 4.28 | AD10: 2.88 | AE10: 4.52 | AF10: 4.8 | AG10: 3.03 | AH10: 4.45 | AI10: 4.79 | AJ10: 1.27 | AK10: 1.26 | AL10: 1.86 | AM10: 1.45 | AN10: 1.93 | AO10: 2.45 | AP10: 3.49 | AQ10: 4.01
A11: Incumplimiento de energía de balance | B11: -0.18 | C11: -0.25 | D11: -0.17 | E11: -0.17 | F11: -0.18 | G11: -0.3 | H11: -0.24 | I11: -0.3 | J11: -0.21 | K11: -0.19 | L11: -0.1 | M11: -0.18 | N11: -0.14 | O11: -0.09 | P11: -0.02 | Q11: -0.02 | R11: -0.06 | S11: -0.09 | T11: -0.07 | U11: -0.08 | V11: -0.1 | W11: -0.12 | X11: -0.22 | Y11: -0.28 | Z11: -0.32 | AA11: -0.46 | AB11: -0.26 | AC11: -0.14 | AD11: -0.04 | AE11: -0.12 | AF11: -0.12 | AG11: -0.13 | AH11: -0.15 | AI11: -0.17 | AJ11: -0.09 | AK11: -0.13 | AL11: -0.36 | AM11: -0.16 | AN11: -0.27 | AO11: -0.37 | AP11: -0.35 | AQ11: -0.41
A12: Coste desvíos | B12: 0.55 | C12: 0.3 | D12: 0.67 | E12: 0.58 | F12: 0.4 | G12: 0.57 | H12: 0.45 | I12: 0.73 | J12: 0.61 | K12: 0.44 | L12: 0.38 | M12: 0.4 | N12: 0.47 | O12: 0.37 | P12: 0.32 | Q12: 0.55 | R12: 0.4 | S12: 0.4 | T12: 0.34 | U12: 0.44 | V12: 0.42 | W12: 0.47 | X12: 0.34 | Y12: 0.4 | Z12: 0.69 | AA12: 0.54 | AB12: 0.54 | AC12: 0.52 | AD12: 0.32 | AE12: 0.44 | AF12: 0.51 | AG12: 0.39 | AH12: 0.46 | AI12: 0.26 | AJ12: 0.37 | AK12: 0.25 | AL12: 0.41 | AM12: 0.44 | AN12: 0.58 | AO12: 0.51 | AP12: 0.44 | AQ12: 0.38
A13: Saldo desvíos | B13: 0.02 | C13: 0.11 | D13: 0.1 | E13: -0.24 | F13: -0.03 | G13: -0.1 | H13: -0.15 | I13: -0.19 | J13: 0.02 | K13: 0.15 | L13: 0.44 | M13: 0.2 | N13: 0.35 | O13: 0.3 | P13: 0.25 | Q13: 0.24 | R13: - | S13: 0.02 | T13: 0.09 | U13: 0.23 | V13: 0.47 | W13: 0.67 | X13: 0.09 | Y13: -0.08 | Z13: 0.1 | AA13: 1.58 | AB13: 0.65 | AC13: 0.11 | AD13: -0.3 | AE13: -0.67 | AF13: -0.58 | AG13: -0.3 | AH13: -0.33 | AI13: -0.52 | AJ13: -0.25 | AK13: -0.24 | AL13: -0.64 | AM13: -0.33 | AN13: -0.38 | AO13: -0.71 | AP13: -0.58 | AQ13: -0.54
A14: Control del factor de potencia | B14: -0.08 | C14: -0.08 | D14: -0.09 | E14: -0.1 | F14: -0.09 | G14: -0.08 | H14: -0.07 | I14: -0.08 | J14: -0.07 | K14: -0.09 | L14: -0.09 | M14: -0.09 | N14: -0.09 | O14: -0.14 | P14: -0.13 | Q14: -0.12 | R14: -0.13 | S14: -0.11 | T14: -0.09 | U14: -0.1 | V14: -0.12 | W14: -0.11 | X14: -0.12 | Y14: -0.11 | Z14: -0.12 | AA14: -0.09 | AB14: -0.1 | AC14: -0.11 | AD14: -0.11 | AE14: -0.09 | AF14: -0.09 | AG14: -0.09 | AH14: -0.1 | AI14: -0.1 | AJ14: -0.02 | AK14: -0.02 | AL14: -0.01 | AM14: -0.1 | AN14: -0.01 | AO14: -0.01 | AP14: -0.01 | AQ14: -0.01
A15: Saldo PO 14.6 | B15: 0.04 | C15: 0.01 | D15: 0.05 | E15: 0.06 | F15: 0.05 | G15: 0.03 | H15: 0.04 | I15: 0.04 | J15: 0.05 | K15: 0.05 | L15: 0.04 | M15: 0.04 | N15: 0.02 | O15: 0.04 | P15: 0.03 | Q15: 0.03 | R15: 0.05 | S15: 0.04 | T15: 0.06 | U15: 0.04 | V15: 0.04 | W15: 0.06 | X15: 0.06 | Y15: 0.03 | Z15: 0.05 | AA15: 0.05 | AB15: 0.05 | AC15: 0.04 | AD15: 0.04 | AE15: 0.05 | AF15: 0.04 | AG15: 0.05 | AH15: 0.05 | AI15: 0.06 | AJ15: 0.04 | AK15: 0.05 | AL15: 0.05 | AM15: 0.05 | AN15: 0.07 | AO15: 0.14 | AP15: 0.06 | AQ15: 0.04
A16: Servicios de ajuste | B16: 13.35 | C16: 7.85 | D16: 10.71 | E16: 10.67 | F16: 9.86 | G16: 8.16 | H16: 7.4 | I16: 7.61 | J16: 8.3 | K16: 13.58 | L16: 14.16 | M16: 10.75 | N16: 8.59 | O16: 9.47 | P16: 12.69 | Q16: 17.12 | R16: 14.22 | S16: 11.48 | T16: 8.2 | U16: 8.75 | V16: 10.87 | W16: 14.38 | X16: 12.36 | Y16: 11.34 | Z16: 11.46 | AA16: 16.32 | AB16: 15.9 | AC16: 17.66 | AD16: 25.62 | AE16: 15.1 | AF16: 14.81 | AG16: 13.4 | AH16: 16.78 | AI16: 17.69 | AJ16: 16.25 | AK16: 13.86 | AL16: 16.19 | AM16: 26.46 | AN16: 30.04 | AO16: 22.89 | AP16: 23.08 | AQ16: 19.57
A17: Pagos por capacidad | B17: 0.34 | C17: 0.35 | D17: 0.24 | E17: 0.16 | F17: 0.17 | G17: 0.19 | H17: 0.33 | I17: 0.2 | J17: 0.19 | K17: 0.17 | L17: 0.23 | M17: 0.3 | N17: 0.35 | O17: 0.33 | P17: 0.19 | Q17: 0.16 | R17: 0.15 | S17: 0.15 | T17: 0.31 | U17: 0.16 | V17: 0.16 | W17: 0.16 | X17: 0.19 | Y17: 0.28 | Z17: 0.27 | AA17: 0.27 | AB17: 0.18 | AC17: 0.14 | AD17: 0.13 | AE17: 0.15 | AF17: 0.28 | AG17: 0.14 | AH17: 0.15 | AI17: 0.14 | AJ17: 0.18 | AK17: 0.27 | AL17: 0.24 | AM17: 0.25 | AN17: 0.17 | AO17: 0.13 | AP17: 0.12 | AQ17: 0.15
A18: Mecanismo ajuste RD-L 10/2022 | B18: 2.9 | C18: -0.71 | D18: - | E18: - | F18: - | G18: - | H18: - | I18: - | J18: - | K18: - | L18: - | M18: - | N18: - | O18: - | P18: - | Q18: - | R18: - | S18: - | T18: - | U18: - | V18: - | W18: - | X18: - | Y18: - | Z18: - | AA18: - | AB18: - | AC18: - | AD18: - | AE18: - | AF18: - | AG18: - | AH18: - | AI18: - | AJ18: - | AK18: - | AL18: - | AM18: - | AN18: - | AO18: - | AP18: - | AQ18: -
A19: Precio total (€/MWh) | B19: 89.68 | C19: 142.91 | D19: 102.79 | E19: 84.87 | F19: 84.26 | G19: 101.98 | H19: 98.59 | I19: 104.6 | J19: 112.41 | K19: 104.3 | L19: 80.3 | M19: 85.38 | N19: 85.73 | O19: 50.48 | P19: 34.19 | Q19: 31.25 | R19: 44.44 | S19: 68.36 | T19: 81.07 | U19: 100.08 | V19: 83.81 | W19: 84.59 | X19: 119.17 | Y19: 125.5 | Z19: 111.93 | AA19: 127.2 | AB19: 71.5 | AC19: 45.45 | AD19: 43.11 | AE19: 87.59 | AF19: 85.38 | AG19: 81.41 | AH19: 77.64 | AI19: 94.27 | AJ19: 76.74 | AK19: 94.12 | AL19: 87.92 | AM19: 42.62 | AN19: 72.47 | AO19: 63.64 | AP19: 75.64 | AQ19: 87.06
A20: Energía de cierre (MWh) | B20: 20838466 | C20: 19363777 | D20: 19448081 | E20: 17224210 | F20: 18089876 | G20: 18719511 | H20: 21334064 | I20: 20297954 | J20: 18387220 | K20: 18602667 | L20: 18943383 | M20: 19935831 | N20: 21055820 | O20: 19159503 | P20: 19517615 | Q20: 18202829 | R20: 18502056 | S20: 18506700 | T20: 21414723 | U20: 20980203 | V20: 18713237 | W20: 19037627 | X20: 18679361 | Y20: 20399772 | Z20: 21691798 | AA20: 19242914 | AB20: 20819390 | AC20: 17848005 | AD20: 18602739 | AE20: 20730203 | AF20: 22211149 | AG20: 20983430 | AH20: 19542167 | AI20: 19196589 | AJ20: 19892075 | AK20: 21396365 | AL20: 22790441 | AM20: 19386376 | AN20: 20284271 | AO20: 18283089 | AP20: 18676014 | AQ20: 20742422
A22: Fecha exportación | B22: 01/05/2026 - 16:21:58
A24: Fuente | B24: Componentes precio energía cierre desglose | Red Eléctrica

Sheet Hoja2
A3: Promedio de SSAA [€/MWh] | B3: Etiquetas de columna
A4: Etiquetas de fila | B4: 2023 | C4: 2024 | D4: 2025 | E4: 2026 | F4: Total general
A5: 1 | B5: 13.35 | C5: 8.59 | D5: 11.46 | E5: 16.19 | F5: 12.3975
A6: 2 | B6: 7.85 | C6: 9.47 | D6: 16.32 | E6: 26.46 | F6: 15.025
A7: 3 | B7: 10.71 | C7: 12.69 | D7: 15.9 | E7: 30.04 | F7: 17.335
A8: 4 | B8: 10.67 | C8: 17.12 | D8: 17.66 | E8: 22.89 | F8: 17.085
A9: 5 | B9: 9.86 | C9: 14.22 | D9: 25.62 | E9: 23.08 | F9: 18.195
A10: 6 | B10: 8.16 | C10: 11.48 | D10: 15.1 | E10: 19.57 | F10: 13.5775
A11: 7 | B11: 7.4 | C11: 8.2 | D11: 14.81 | F11: 10.136667
A12: 8 | B12: 7.61 | C12: 8.75 | D12: 13.4 | F12: 9.92
A13: 9 | B13: 8.3 | C13: 10.87 | D13: 16.78 | F13: 11.983333
A14: 10 | B14: 13.58 | C14: 14.38 | D14: 17.69 | F14: 15.216667
A15: 11 | B15: 14.16 | C15: 12.36 | D15: 16.25 | F15: 14.256667
A16: 12 | B16: 10.75 | C16: 11.34 | D16: 13.86 | F16: 11.983333
A17: Total general | B17: 10.2 | C17: 11.6225 | D17: 16.2375 | E17: 23.038333 | F17: 14.165476

Sheet ESTUDIO SSAA
A2: Servicios de ajuste | B2: € / MWh | E2: FECHA | F2: AÑO | G2: MES | H2: SSAA [€/MWh]
A3: 44927 | B3: 13.35 | E3: =A3 -> 44927 | F3: =YEAR(A3) -> 2023 | G3: =MONTH(A3) -> 1 | H3: =B3 -> 13.35 | J3: MEDIA ULT 12 MESES | K3: =AVERAGE(H33:H44) -> 19.251667
A4: 44958 | B4: 7.85 | E4: =A4 -> 44958 | F4: =YEAR(A4) -> 2023 | G4: =MONTH(A4) -> 2 | H4: =B4 -> 7.85 | J4: MEDIA ULT 24 MESES | K4: =AVERAGE(H21:H44) -> 16.624167
A5: 44986 | B5: 10.71 | E5: =A5 -> 44986 | F5: =YEAR(A5) -> 2023 | G5: =MONTH(A5) -> 3 | H5: =B5 -> 10.71
A6: 45017 | B6: 10.67 | E6: =A6 -> 45017 | F6: =YEAR(A6) -> 2023 | G6: =MONTH(A6) -> 4 | H6: =B6 -> 10.67 | J6: SSAA BASE | K6: =0.7*K3+K4*0.3 -> 18.463417
A7: 45047 | B7: 9.86 | E7: =A7 -> 45047 | F7: =YEAR(A7) -> 2023 | G7: =MONTH(A7) -> 5 | H7: =B7 -> 9.86
A8: 45078 | B8: 8.16 | E8: =A8 -> 45078 | F8: =YEAR(A8) -> 2023 | G8: =MONTH(A8) -> 6 | H8: =B8 -> 8.16
A9: 45108 | B9: 7.4 | E9: =A9 -> 45108 | F9: =YEAR(A9) -> 2023 | G9: =MONTH(A9) -> 7 | H9: =B9 -> 7.4 | J9: ESTACIONABILIDAD | L9: PESO EN € / MWh
A10: 45139 | B10: 7.61 | E10: =A10 -> 45139 | F10: =YEAR(A10) -> 2023 | G10: =MONTH(A10) -> 8 | H10: =B10 -> 7.61 | J10: ENERO | K10: 1 | L10: =AVERAGEIF($G$3:$G$44,1,$H$3:$H$44)/AVERAGE($H$3:$H$44) -> 0.87519119 | M10: =IF(L10<1,1-L10,L10-1) -> 0.12480881 | N10: =IF(L10<1,"por debajo","por encima") -> por debajo
A11: 45170 | B11: 8.3 | E11: =A11 -> 45170 | F11: =YEAR(A11) -> 2023 | G11: =MONTH(A11) -> 9 | H11: =B11 -> 8.3 | J11: FEBRERO | K11: 2 | L11: =AVERAGEIF($G$3:$G$44,2,$H$3:$H$44)/AVERAGE($H$4:$H$44) -> 1.0591902 | M11: =IF(L11<1,1-L11,L11-1) -> 0.059190165 | N11: =IF(L11<1,"por debajo","por encima") -> por encima
A12: 45200 | B12: 13.58 | E12: =A12 -> 45200 | F12: =YEAR(A12) -> 2023 | G12: =MONTH(A12) -> 10 | H12: =B12 -> 13.58 | J12: MARZO | K12: 3 | L12: =AVERAGEIF($G$3:$G$44,3,$H$3:$H$44)/AVERAGE($H$3:$H$44) -> 1.2237499 | M12: =IF(L12<1,1-L12,L12-1) -> 0.22374989 | N12: =IF(L12<1,"por debajo","por encima") -> por encima
A13: 45231 | B13: 14.16 | E13: =A13 -> 45231 | F13: =YEAR(A13) -> 2023 | G13: =MONTH(A13) -> 11 | H13: =B13 -> 14.16 | J13: ABRIL | K13: 4 | L13: =AVERAGEIF($G$3:$G$44,4,$H$3:$H$44)/AVERAGE($H$3:$H$44) -> 1.2061014 | M13: =IF(L13<1,1-L13,L13-1) -> 0.20610135 | N13: =IF(L13<1,"por debajo","por encima") -> por encima
A14: 45261 | B14: 10.75 | E14: =A14 -> 45261 | F14: =YEAR(A14) -> 2023 | G14: =MONTH(A14) -> 12 | H14: =B14 -> 10.75 | J14: MAYO | K14: 5 | L14: =AVERAGEIF($G$3:$G$41,5,$H$3:$H$41)/AVERAGE($H$3:$H$41) -> 1.2204152 | M14: =IF(L14<1,1-L14,L14-1) -> 0.22041518 | N14: =IF(L14<1,"por debajo","por encima") -> por encima
A15: 45292 | B15: 8.59 | E15: =A15 -> 45292 | F15: =YEAR(A15) -> 2024 | G15: =MONTH(A15) -> 1 | H15: =B15 -> 8.59 | J15: JUNIO | K15: 6 | L15: =AVERAGEIF($G$3:$G$44,6,$H$3:$H$44)/AVERAGE($H$3:$H$44) -> 0.95849231 | M15: =IF(L15<1,1-L15,L15-1) -> 0.04150769 | N15: =IF(L15<1,"por debajo","por encima") -> por debajo
A16: 45323 | B16: 9.47 | E16: =A16 -> 45323 | F16: =YEAR(A16) -> 2024 | G16: =MONTH(A16) -> 2 | H16: =B16 -> 9.47 | J16: JULIO | K16: 7 | L16: =AVERAGEIF($G$3:$G$44,7,$H$3:$H$44)/AVERAGE($H$3:$H$44) -> 0.71558955 | M16: =IF(L16<1,1-L16,L16-1) -> 0.28441045 | N16: =IF(L16<1,"por debajo","por encima") -> por debajo
A17: 45352 | B17: 12.69 | E17: =A17 -> 45352 | F17: =YEAR(A17) -> 2024 | G17: =MONTH(A17) -> 3 | H17: =B17 -> 12.69 | J17: AGOSTO | K17: 8 | L17: =AVERAGEIF($G$3:$G$44,8,$H$3:$H$44)/AVERAGE($H$3:$H$44) -> 0.70029414 | M17: =IF(L17<1,1-L17,L17-1) -> 0.29970586 | N17: =IF(L17<1,"por debajo","por encima") -> por debajo
A18: 45383 | B18: 17.12 | E18: =A18 -> 45383 | F18: =YEAR(A18) -> 2024 | G18: =MONTH(A18) -> 4 | H18: =B18 -> 17.12 | J18: SEPTIEMBRE | K18: 9 | L18: =AVERAGEIF($G$3:$G$44,9,$H$3:$H$44)/AVERAGE($H$3:$H$44) -> 0.84595344 | M18: =IF(L18<1,1-L18,L18-1) -> 0.15404656 | N18: =IF(L18<1,"por debajo","por encima") -> por debajo
A19: 45413 | B19: 14.22 | E19: =A19 -> 45413 | F19: =YEAR(A19) -> 2024 | G19: =MONTH(A19) -> 5 | H19: =B19 -> 14.22 | J19: OCTUBRE | K19: 10 | L19: =AVERAGEIF($G$3:$G$44,10,$H$3:$H$44)/AVERAGE($H$3:$H$44) -> 1.0742079 | M19: =IF(L19<1,1-L19,L19-1) -> 0.074207917 | N19: =IF(L19<1,"por debajo","por encima") -> por encima
A20: 45444 | B20: 11.48 | E20: =A20 -> 45444 | F20: =YEAR(A20) -> 2024 | G20: =MONTH(A20) -> 6 | H20: =B20 -> 11.48 | J20: NOVIEMBRE | K20: 11 | L20: =AVERAGEIF($G$3:$G$44,11,$H$3:$H$44)/AVERAGE($H$3:$H$44) -> 1.0064375 | M20: =IF(L20<1,1-L20,L20-1) -> 0.0064375158 | N20: =IF(L20<1,"por debajo","por encima") -> por encima
A21: 45474 | B21: 8.2 | E21: =A21 -> 45474 | F21: =YEAR(A21) -> 2024 | G21: =MONTH(A21) -> 7 | H21: =B21 -> 8.2 | J21: DICIEMBRE | K21: 12 | L21: =AVERAGEIF($G$3:$G$44,12,$H$3:$H$44)/AVERAGE($H$3:$H$44) -> 0.84595344 | M21: =IF(L21<1,1-L21,L21-1) -> 0.15404656 | N21: =IF(L21<1,"por debajo","por encima") -> por debajo
A22: 45505 | B22: 8.75 | E22: =A22 -> 45505 | F22: =YEAR(A22) -> 2024 | G22: =MONTH(A22) -> 8 | H22: =B22 -> 8.75
A23: 45536 | B23: 10.87 | E23: =A23 -> 45536 | F23: =YEAR(A23) -> 2024 | G23: =MONTH(A23) -> 9 | H23: =B23 -> 10.87
A24: 45566 | B24: 14.38 | E24: =A24 -> 45566 | F24: =YEAR(A24) -> 2024 | G24: =MONTH(A24) -> 10 | H24: =B24 -> 14.38
A25: 45597 | B25: 12.36 | E25: =A25 -> 45597 | F25: =YEAR(A25) -> 2024 | G25: =MONTH(A25) -> 11 | H25: =B25 -> 12.36
A26: 45627 | B26: 11.34 | E26: =A26 -> 45627 | F26: =YEAR(A26) -> 2024 | G26: =MONTH(A26) -> 12 | H26: =B26 -> 11.34 | J26: PRIMA RIESGO SSAA | K26: =MAX(0,_xlfn.PERCENTILE.INC(H21:H44,[1]SSAA!$C$7)-AVERAGE(H21:H44)) -> 4.2738333 | L26: € / MWh
A27: 45658 | B27: 11.46 | E27: =A27 -> 45658 | F27: =YEAR(A27) -> 2025 | G27: =MONTH(A27) -> 1 | H27: =B27 -> 11.46 | J27: TENGO EN CUENTA EL PERCENTIL 80
A28: 45689 | B28: 16.32 | E28: =A28 -> 45689 | F28: =YEAR(A28) -> 2025 | G28: =MONTH(A28) -> 2 | H28: =B28 -> 16.32
A29: 45717 | B29: 15.9 | E29: =A29 -> 45717 | F29: =YEAR(A29) -> 2025 | G29: =MONTH(A29) -> 3 | H29: =B29 -> 15.9
A30: 45748 | B30: 17.66 | E30: =A30 -> 45748 | F30: =YEAR(A30) -> 2025 | G30: =MONTH(A30) -> 4 | H30: =B30 -> 17.66
A31: 45778 | B31: 25.62 | E31: =A31 -> 45778 | F31: =YEAR(A31) -> 2025 | G31: =MONTH(A31) -> 5 | H31: =B31 -> 25.62
A32: 45809 | B32: 15.1 | E32: =A32 -> 45809 | F32: =YEAR(A32) -> 2025 | G32: =MONTH(A32) -> 6 | H32: =B32 -> 15.1
A33: 45839 | B33: 14.81 | E33: =A33 -> 45839 | F33: =YEAR(A33) -> 2025 | G33: =MONTH(A33) -> 7 | H33: =B33 -> 14.81
A34: 45870 | B34: 13.4 | E34: =A34 -> 45870 | F34: =YEAR(A34) -> 2025 | G34: =MONTH(A34) -> 8 | H34: =B34 -> 13.4
A35: 45901 | B35: 16.78 | E35: =A35 -> 45901 | F35: =YEAR(A35) -> 2025 | G35: =MONTH(A35) -> 9 | H35: =B35 -> 16.78
A36: 45931 | B36: 17.69 | E36: =A36 -> 45931 | F36: =YEAR(A36) -> 2025 | G36: =MONTH(A36) -> 10 | H36: =B36 -> 17.69
A37: 45962 | B37: 16.25 | E37: =A37 -> 45962 | F37: =YEAR(A37) -> 2025 | G37: =MONTH(A37) -> 11 | H37: =B37 -> 16.25
A38: 45992 | B38: 13.86 | E38: =A38 -> 45992 | F38: =YEAR(A38) -> 2025 | G38: =MONTH(A38) -> 12 | H38: =B38 -> 13.86
A39: 46023 | B39: 16.19 | E39: =A39 -> 46023 | F39: =YEAR(A39) -> 2026 | G39: =MONTH(A39) -> 1 | H39: =B39 -> 16.19
... A44: 46174 | B44: 19.57 | E44: =A44 -> 46174 | F44: =YEAR(A44) -> 2026 | G44: =MONTH(A44) -> 6 | H44: =B44 -> 19.57
E48: PROMEDIOS ANUEALES
...

Sheet OFERTA
B2: FECHA | C2: AÑO | D2: MES | E2: I.ESTACIONALIDAD [€/MWh] | F2: SSAA BASE [€/MWh] | G2: SSAA ESPERADO [€/MWh] | H2: PRIMA RIESGO [€/MWh] | J2: SSAA FINAL | K2: =IF(OR([1]SSAA!$C$2="",[1]SSAA!$C$3=""),"",IFERROR(AVERAGEIFS($J$3:$J$17,$B$3:$B$17,">="&DATE(YEAR([1]SSAA!$C$2),MONTH([1]SSAA!$C$2),1),$B$3:$B$17,"<="&EOMONTH([1]SSAA!$C$3,0)),"")) -> 22.297066 | L2: Este es el valor que meteria en la calculadora
B3: 46113 | C3: =YEAR(B3) -> 2026 | D3: =MONTH(B3) -> 4 | E3: =VLOOKUP(D3,'ESTUDIO SSAA'!K10:L21,2,FALSE) -> 1.2061014 | F3: 18.463417 | G3: =F3*E3 -> 22.268752 | H3: ='ESTUDIO SSAA'!$K$26 -> 4.2738333 | J3: =G3+H3 -> 26.542585
B4: 46143 | C4: =YEAR(B4) -> 2026 | D4: =MONTH(B4) -> 5 | E4: =VLOOKUP(D4,'ESTUDIO SSAA'!K11:L22,2,FALSE) -> 1.2204152 | F4: 18.463417 | G4: =F4*E4 -> 22.533034 | H4: ='ESTUDIO SSAA'!$K$26 -> 4.2738333 | J4: =G4+H4 -> 26.806867
B5: 46174 | C5: =YEAR(B5) -> 2026 | D5: =MONTH(B5) -> 6 | E5: =VLOOKUP(D5,'ESTUDIO SSAA'!K12:L23,2,FALSE) -> 0.95849231 | F5: 18.463417 | G5: =F5*E5 -> 17.697043 | H5: ='ESTUDIO SSAA'!$K$26 -> 4.2738333 | J5: =G5+H5 -> 21.970876
B6: 46204 | C6: =YEAR(B6) -> 2026 | D6: =MONTH(B6) -> 7 | E6: =VLOOKUP(D6,'ESTUDIO SSAA'!K13:L24,2,FALSE) -> 0.71558955 | F6: 18.463417 | G6: =F6*E6 -> 13.212228 | H6: ='ESTUDIO SSAA'!$K$26 -> 4.2738333 | J6: =G6+H6 -> 17.486061
B7: 46235 | C7: =YEAR(B7) -> 2026 | D7: =MONTH(B7) -> 8 | E7: =VLOOKUP(D7,'ESTUDIO SSAA'!K14:L25,2,FALSE) -> 0.70029414 | F7: 18.463417 | G7: =F7*E7 -> 12.929823 | H7: ='ESTUDIO SSAA'!$K$26 -> 4.2738333 | J7: =G7+H7 -> 17.203656
B8: 46266 | C8: =YEAR(B8) -> 2026 | D8: =MONTH(B8) -> 9 | E8: =VLOOKUP(D8,'ESTUDIO SSAA'!K15:L26,2,FALSE) -> 0.84595344 | F8: 18.463417 | G8: =F8*E8 -> 15.619191 | H8: ='ESTUDIO SSAA'!$K$26 -> 4.2738333 | J8: =G8+H8 -> 19.893024
B9: 46296 | C9: =YEAR(B9) -> 2026 | D9: =MONTH(B9) -> 10 | E9: =VLOOKUP(D9,'ESTUDIO SSAA'!K16:L27,2,FALSE) -> 1.0742079 | F9: 18.463417 | G9: =F9*E9 -> 19.833548 | H9: ='ESTUDIO SSAA'!$K$26 -> 4.2738333 | J9: =G9+H9 -> 24.107382
B10: 46327 | C10: =YEAR(B10) -> 2026 | D10: =MONTH(B10) -> 11 | E10: =VLOOKUP(D10,'ESTUDIO SSAA'!K17:L28,2,FALSE) -> 1.0064375 | F10: 18.463417 | G10: =F10*E10 -> 18.582275 | H10: ='ESTUDIO SSAA'!$K$26 -> 4.2738333 | J10: =G10+H10 -> 22.856109
B11: 46357 | C11: =YEAR(B11) -> 2026 | D11: =MONTH(B11) -> 12 | E11: =VLOOKUP(D11,'ESTUDIO SSAA'!K18:L29,2,FALSE) -> 0.84595344 | F11: 18.463417 | G11: =F11*E11 -> 15.619191 | H11: ='ESTUDIO SSAA'!$K$26 -> 4.2738333 | J11: =G11+H11 -> 19.893024
B12: 46388 | C12: =YEAR(B12) -> 2027 | D12: =MONTH(B12) -> 1 | E12: =VLOOKUP(D12,'ESTUDIO SSAA'!K10:L21,2,FALSE) -> 0.87519119 | F12: 18.463417 | G12: =F12*E12 -> 16.15902 | H12: ='ESTUDIO SSAA'!$K$26 -> 4.2738333 | J12: =G12+H12 -> 20.432853
B13: 46419 | C13: =YEAR(B13) -> 2027 | D13: =MONTH(B13) -> 2 | E13: =VLOOKUP(D13,'ESTUDIO SSAA'!K11:L22,2,FALSE) -> 1.0591902 | F13: 18.463417 | G13: =F13*E13 -> 19.556269 | H13: ='ESTUDIO SSAA'!$K$26 -> 4.2738333 | J13: =G13+H13 -> 23.830103
B14: 46447 | C14: =YEAR(B14) -> 2027 | D14: =MONTH(B14) -> 3 | E14: =VLOOKUP(D14,'ESTUDIO SSAA'!K12:L23,2,FALSE) -> 1.2237499 | F14: 18.463417 | G14: =F14*E14 -> 22.594604 | H14: ='ESTUDIO SSAA'!$K$26 -> 4.2738333 | J14: =G14+H14 -> 26.868438
B15: 46478 | C15: =YEAR(B15) -> 2027 | D15: =MONTH(B15) -> 4 | E15: =VLOOKUP(D15,'ESTUDIO SSAA'!K13:L24,2,FALSE) -> 1.2061014 | F15: 18.463417 | G15: =F15*E15 -> 22.268752 | H15: ='ESTUDIO SSAA'!$K$26 -> 4.2738333 | J15: =G15+H15 -> 26.542585
B16: 46508 | C16: =YEAR(B16) -> 2027 | D16: =MONTH(B16) -> 5 | E16: =VLOOKUP(D16,'ESTUDIO SSAA'!K14:L25,2,FALSE) -> 1.2204152 | F16: 18.463417 | G16: =F16*E16 -> 22.533034 | H16: ='ESTUDIO SSAA'!$K$26 -> 4.2738333 | J16: =G16+H16 -> 26.806867
B17: 46539 | C17: =YEAR(B17) -> 2027 | D17: =MONTH(B17) -> 6 | E17: =VLOOKUP(D17,'ESTUDIO SSAA'!K15:L26,2,FALSE) -> 0.95849231 | F17: 18.463417 | G17: =F17*E17 -> 17.697043 | H17: ='ESTUDIO SSAA'!$K$26 -> 4.2738333 | J17: =G17+H17 -> 21.970876

Sheet Hoja1
A1: Servicios de ajuste | B1: € / MWh
A2: 45292 | B2: 8.59 | C2: 11.6225 | D2: PROMEDIOS ANUEALES
A3: 45323 | B3: 9.47 | C3: 11.6225 | D3: 2023 | E3: 2024 | F3: 2025 | G3: 2026
A4: 45352 | B4: 12.69 | C4: 11.6225 | D4: 10.2 | E4: 11.6225 | F4: 16.2375 | G4: 24.23
A5: 45383 | B5: 17.12 | C5: 11.6225
A6: 45413 | B6: 14.22 | C6: 11.6225
A7: 45444 | B7: 11.48 | C7: 11.6225
A8: 45474 | B8: 8.2 | C8: 11.6225
A9: 45505 | B9: 8.75 | C9: 11.6225
A10: 45536 | B10: 10.87 | C10: 11.6225
A11: 45566 | B11: 14.38 | C11: 11.6225
A12: 45597 | B12: 12.36 | C12: 11.6225
A13: 45627 | B13: 11.34 | C13: 11.6225
A14: 45658 | B14: 11.46 | C14: 16.2375
A15: 45689 | B15: 16.32 | C15: 16.2375
A16: 45717 | B16: 15.9 | C16: 16.2375
... A28: 46082 | B28: 30.04 | C28: 24.23

Sheet Hoja4
A3: Promedio de SSAA [€/MWh] | B3: Etiquetas de columna
A4: MESES | B4: 2023 | C4: 2024 | D4: 2025 | E4: 2026 | F4: Total general
A5: 1 | B5: 13.35 | C5: 8.59 | D5: 11.46 | E5: 16.19 | F5: 12.3975
A6: 2 | B6: 7.85 | C6: 9.47 | D6: 16.32 | E6: 26.46 | F6: 15.025
A7: 3 | B7: 10.71 | C7: 12.69 | D7: 15.9 | E7: 30.04 | F7: 17.335
A8: 4 | B8: 10.67 | C8: 17.12 | D8: 17.66 | F8: 15.15
A9: 5 | B9: 9.86 | C9: 14.22 | D9: 25.62 | F9: 16.566667
A10: 6 | B10: 8.16 | C10: 11.48 | D10: 15.1 | F10: 11.58
A11: 7 | B11: 7.4 | C11: 8.2 | D11: 14.81 | F11: 10.136667
A12: 8 | B12: 7.61 | C12: 8.75 | D12: 13.4 | F12: 9.92
A13: 9 | B13: 8.3 | C13: 10.87 | D13: 16.78 | F13: 11.983333
A14: 10 | B14: 13.58 | C14: 14.38 | D14: 17.69 | F14: 15.216667
A15: 11 | B15: 14.16 | C15: 12.36 | D15: 16.25 | F15: 14.256667
A16: 12 | B16: 10.75 | C16: 11.34 | D16: 13.86 | F16: 11.983333
A17: Total general | B17: 10.2 | C17: 11.6225 | D17: 16.2375 | E17: 24.23 | F17: 13.574615
